Workbook

Sheet 통합 시나리오 설계 철학
A1: 24개 시나리오(AS-IS) | C1: 12개 시나리오(to-be) | E1: - 5단계로 구분시 시나리오 개수(1:신용/체크 , 2:신규, 추가 3: 공용/개별 4:부서내추가/부서추가, 5:대표자,대리인) | M1: - 4단계 구분시 시나리오 개수(1:신용/체크 , 2:신규, 추가 3: 공용/개별 4:부서내추가/부서추가)
A2: No,1단계,2단계,3단계,4단계,5단계 | C2: 아래는 12가지 경우의 수를 텍스트로 연결해서 표시한 목록입니다: | E2: 신용 | F2: 신용 | G2: 체크 | H2: 체크 | I2: 합계 | M2: 신용 | N2: 신용 | O2: 체크 | P2: 체크 | Q2: 합계
A3: 1,신용,신규,공용,대표자,- | E3: 신규 | F3: 추가 | G3: 신규 | H3: 추가 | M3: 신규 | N3: 추가 | O3: 신규 | P3: 추가
A4: 2,신용,신규,공용,대리인,- | C4: 신용 | E4: 4 | F4: 8 | G4: 4 | H4: 8 | I4: =H4+G4+F4+E4 -> 24 | M4: 2 | N4: 4 | O4: 2 | P4: 4 | Q4: =P4+O4+N4+M4 -> 12
A5: 3,신용,신규,개별,대표자,- | E5: - 신규 발급은 부서내 추가/부서 추가 개념 미존재
A6: 4,신용,신규,개별,대리인,- | C6: 신용 → 신규 → 공용
A7: 5,신용,추가,공용,대표자,부서내추가발급 | C7: 신용 → 신규 → 개별 | E7: - 현재 신규발급 시나리오 8개 확보 되어 있으며 추가 발급의 일부 시나리오 확보 (추가_공용_부서내 발급, 추가_공용_부서추가) - 체크 카드의 경우 추가 발급 확보 시나리오 확보 불가 > 발급 테스트 케이스를 구하기 어려움 - 현재 24개에 해당하는 각각의 시나리오를 시나리오 베이스로 만드는 것은 현실적으로 확인 시간 소요 등 감안 시 1. 너무 많은 시간이 소요됨 2. 여럿이 공동작업 시 기준이 모호하여 확인 어려움 ㅌ - 상기 문제를 고려하여 24개의 시나리오를 트리 구조로 분개 하여 계층별로 만들 고자함 - 이 시나리오의 기본 전제 1. 로그인 없음 2. 대표자 /대리인 분개 없이 하나의 흐름으로 통합 > 시나리오 및 분개 경우의 수 최소화 2. 사업자 번호로 처리계에서 회원원장 조회 - 신규, 추가 구분 3. CDD 업데이트 대상 여부 조회 4. 사업자 번호 기준으로 - 기존 회원 정보(청구 등) 동일 조회 활용 6. 처리계와 연동되어 정보 조회 전에 "공동인증서" 인증필요 > 정보 보호 이슈 대응
A8: 6,신용,추가,공용,대표자,부서 추가 | C8: 신용 → 추가 → 공용 → 부서내발급
A9: 7,신용,추가,공용,대리인,부서내추가발급 | C9: 신용 → 추가 → 공용 → 부서추가
A10: 8,신용,추가,공용,대리인,부서 추가 | C10: 신용 → 추가 → 개별 → 부서내발급
A11: 9,신용,추가,개별,대표자,부서내추가발급 | C11: 신용 → 추가 → 개별 → 부서추가
A12: 10,신용,추가,개별,대표자,부서 추가
A13: 11,신용,추가,개별,대리인,부서내추가발급
A14: 12,신용,추가,개별,대리인,부서 추가 | C14: 체크
A15: 13,체크,신규,공용,대표자,-
A16: 14,체크,신규,공용,대리인,- | C16: 체크 → 신규 → 공용
A17: 15,체크,신규,개별,대표자,- | C17: 체크 → 신규 → 개별
A18: 16,체크,신규,개별,대리인,- | C18: 체크 → 추가 → 공용 → 부서내발급
A19: 17,체크,추가,공용,대표자,부서내추가발급 | C19: 체크 → 추가 → 공용 → 부서추가
A20: 18,체크,추가,공용,대표자,부서 추가 | C20: 체크 → 추가 → 개별 → 부서내발급
A21: 19,체크,추가,공용,대리인,부서내추가발급 | C21: 체크 → 추가 → 개별 → 부서추가
A22: 20,체크,추가,공용,대리인,부서 추가
A23: 21,체크,추가,개별,대표자,부서내추가발급
A24: 22,체크,추가,개별,대표자,부서 추가
A25: 23,체크,추가,개별,대리인,부서내추가발급
A26: 24,체크,추가,개별,대리인,부서 추가

Sheet 법사자_신용
A1: 분개 시점 | B1: 시나리오수
A2: 신용 | B2: 1 | P2: 신용
P3: 상품선택(분개)
O4: =VLOOKUP(P4,PC웹_서비스목록ID!$A$1:$E$111,2,FALSE) -> 0001 | P4: 사업자번호입력
O5: =VLOOKUP(P5,PC웹_서비스목록ID!$A$1:$E$111,2,FALSE) -> 0002 | P5: 신규 대상 통합 발급 안내
P7: 신규_추가 팝업 창(분개)
A8: 신규/추가 | B8: 2 | O8: 신용_신규 분개 | Q8: 신용_추가 분개
N9: =VLOOKUP(O9,PC웹_서비스목록ID!$A$1:$E$111,2,FALSE) -> 0002 | O9: 신규 대상 통합 발급 안내 | P9: =VLOOKUP(Q9,PC웹_서비스목록ID!$A$1:$E$111,2,FALSE) -> 0003 | Q9: 추가 대상 통합 발급 안내
N10: =VLOOKUP(O10,PC웹_서비스목록ID!$A$1:$E$111,2,FALSE) -> 0004 | O10: 준비사항 | P10: =VLOOKUP(Q10,PC웹_서비스목록ID!$A$1:$E$111,2,FALSE) -> 0004 | Q10: 준비사항
N11: =VLOOKUP(O11,PC웹_서비스목록ID!$A$1:$E$111,2,FALSE) -> 0005 | O11: 제출서류 | P11: =VLOOKUP(Q11,PC웹_서비스목록ID!$A$1:$E$111,2,FALSE) -> 0005 | Q11: 제출서류
N12: =VLOOKUP(O12,PC웹_서비스목록ID!$A$1:$E$111,2,FALSE) -> 0006 | O12: 서류자동제출서비스 | P12: =VLOOKUP(Q12,PC웹_서비스목록ID!$A$1:$E$111,2,FALSE) -> 0006 | Q12: 서류자동제출서비스
N13: =VLOOKUP(O13,PC웹_서비스목록ID!$A$1:$E$111,2,FALSE) -> 0007 | O13: 유의사항 | P13: =VLOOKUP(Q13,PC웹_서비스목록ID!$A$1:$E$111,2,FALSE) -> 0007 | Q13: 유의사항
N14: =VLOOKUP(O14,PC웹_서비스목록ID!$A$1:$E$111,2,FALSE) -> 0008 | O14: 법인 공동인증서(기업용)이용안내 | P14: =VLOOKUP(Q14,PC웹_서비스목록ID!$A$1:$E$111,2,FALSE) -> 0008 | Q14: 법인 공동인증서(기업용)이용안내
O15: 공용/개별 팝업창(분개) | Q15: 공용/개별 팝업창 (분개)
O16: -
O17: -
O18: -
O19: -
O20: -
O21: -
A22: 개별/공용 | B22: 3 | K22: 신용_신규_공용 분개_대표 OR 대리인 | N22: 신용_신규_개별 분개_대표 OR 대리인 | R22: 신용_추가_개별 분개 | X22: 신용_추가_공용 분개
J23: =VLOOKUP(K23,PC웹_서비스목록ID!$A$1:$E$111,2,FALSE) -> 0009 | K23: 신용카드 상품 약관동의 | M23: =VLOOKUP(N23,PC웹_서비스목록ID!$A$1:$E$111,2,FALSE) -> 0009 | N23: 신용카드 상품 약관동의 | R23: - | W23: =VLOOKUP(X23,PC웹_서비스목록ID!$A$1:$E$111,2,FALSE) -> 0009 | X23: 신용카드 상품 약관동의
J24: =VLOOKUP(K24,PC웹_서비스목록ID!$A$1:$E$111,2,FALSE) -> 0010 | K24: 신청인정보 | M24: =VLOOKUP(N24,PC웹_서비스목록ID!$A$1:$E$111,2,FALSE) -> 0035 | N24: 개별 카드 회원 동의서 작성안내 | O24: 신청인 CDD 조건부 검증(신설필요) | Q24: =VLOOKUP(R24,PC웹_서비스목록ID!$A$1:$E$111,2,FALSE) -> #N/A | R24: 발급 대상 분서 팝업(신설필요) | W24: =VLOOKUP(X24,PC웹_서비스목록ID!$A$1:$E$111,2,FALSE) -> #N/A | X24: 발급 대상 분서 팝업(신설필요)
J25: =VLOOKUP(K25,PC웹_서비스목록ID!$A$1:$E$111,2,FALSE) -> 0011 | K25: 신청자 신용정보 조회 이용 동의(대표자 /대리인) 신설필요 | M25: =VLOOKUP(N25,PC웹_서비스목록ID!$A$1:$E$111,2,FALSE) -> 0036 | N25: 개별카드 사용자 개인명의계좌 등록- 개별 | R25: 발급대상부서 분개 발생 | W25: =VLOOKUP(X25,PC웹_서비스목록ID!$A$1:$E$111,2,FALSE) -> #N/A | X25: 부서내 추가발급_부서추가 분개
J26: =VLOOKUP(K26,PC웹_서비스목록ID!$A$1:$E$111,2,FALSE) -> 0012 | K26: 신청인 본인인증 | M26: =VLOOKUP(N26,PC웹_서비스목록ID!$A$1:$E$111,2,FALSE) -> 0037 | N26: 개별카드 발급 대상 고객 정보- 개별
J27: =VLOOKUP(K27,PC웹_서비스목록ID!$A$1:$E$111,2,FALSE) -> 0013 | K27: 신청인 CDD 조건부 검증(신설필요) | M27: =VLOOKUP(N27,PC웹_서비스목록ID!$A$1:$E$111,2,FALSE) -> 0038 | N27: 개별카드 동의 조회(조회하기)- 개별
J28: =VLOOKUP(K28,PC웹_서비스목록ID!$A$1:$E$111,2,FALSE) -> 0014 | K28: 대표자 정보 | M28: =VLOOKUP(N28,PC웹_서비스목록ID!$A$1:$E$111,2,FALSE) -> 0039 | N28: 개인신용정보 동의서 - 개별
J29: =VLOOKUP(K29,PC웹_서비스목록ID!$A$1:$E$111,2,FALSE) -> 0015 | K29: 사업자 정보 | M29: =VLOOKUP(N29,PC웹_서비스목록ID!$A$1:$E$111,2,FALSE) -> 0040 | N29: 개별카드 동의 조회(신청하기) - 개별
J30: =VLOOKUP(K30,PC웹_서비스목록ID!$A$1:$E$111,2,FALSE) -> 0016 | K30: 법인 정보 | M30: =VLOOKUP(N30,PC웹_서비스목록ID!$A$1:$E$111,2,FALSE) -> 0010 | N30: 신청인정보
J31: =VLOOKUP(K31,PC웹_서비스목록ID!$A$1:$E$111,2,FALSE) -> 0017 | K31: EDD정보 | M31: =VLOOKUP(N31,PC웹_서비스목록ID!$A$1:$E$111,2,FALSE) -> 0011 | N31: 신청자 신용정보 조회 이용 동의(대표자 /대리인) 신설필요
J32: =VLOOKUP(K32,PC웹_서비스목록ID!$A$1:$E$111,2,FALSE) -> 0018 | K32: 필수확인사항 | M32: =VLOOKUP(N32,PC웹_서비스목록ID!$A$1:$E$111,2,FALSE) -> 0012 | N32: 신청인 본인인증
A33: 부서내추가/부서부가 | J33: =VLOOKUP(K33,PC웹_서비스목록ID!$A$1:$E$111,2,FALSE) -> 0019 | K33: 이용한도 | M33: =VLOOKUP(N33,PC웹_서비스목록ID!$A$1:$E$111,2,FALSE) -> 0013 | N33: 신청인 CDD 조건부 검증(신설필요) | Q33: 신용_추가_개별_부서내 추가발급 분개 | S33: 신용_추가_개별_부서 추가 분개 | W33: 신용_추가_공용_부서내 추가발급 분개 | Y33: 신용_추가공용_부서 추가 분개
J34: =VLOOKUP(K34,PC웹_서비스목록ID!$A$1:$E$111,2,FALSE) -> 0020 | K34: 명세서 받으실 곳 | M34: =VLOOKUP(N34,PC웹_서비스목록ID!$A$1:$E$111,2,FALSE) -> 0014 | N34: 대표자 정보 | P34: =VLOOKUP(Q34,PC웹_서비스목록ID!$A$1:$E$111,2,FALSE) -> 0035 | Q34: 개별 카드 회원 동의서 작성안내 | R34: =VLOOKUP(S34,PC웹_서비스목록ID!$A$1:$E$111,2,FALSE) -> 0035 | S34: 개별 카드 회원 동의서 작성안내 | V34: =VLOOKUP(W34,PC웹_서비스목록ID!$A$1:$E$111,2,FALSE) -> 0010 | W34: 신청인정보 | X34: =VLOOKUP(Y34,PC웹_서비스목록ID!$A$1:$E$111,2,FALSE) -> 0010 | Y34: 신청인정보
J35: =VLOOKUP(K35,PC웹_서비스목록ID!$A$1:$E$111,2,FALSE) -> 0021 | K35: 카드선택 | M35: =VLOOKUP(N35,PC웹_서비스목록ID!$A$1:$E$111,2,FALSE) -> 0015 | N35: 사업자 정보 | P35: =VLOOKUP(Q35,PC웹_서비스목록ID!$A$1:$E$111,2,FALSE) -> 0036 | Q35: 개별카드 사용자 개인명의계좌 등록- 개별 | R35: =VLOOKUP(S35,PC웹_서비스목록ID!$A$1:$E$111,2,FALSE) -> 0036 | S35: 개별카드 사용자 개인명의계좌 등록- 개별 | V35: =VLOOKUP(W35,PC웹_서비스목록ID!$A$1:$E$111,2,FALSE) -> 0011 | W35: 신청자 신용정보 조회 이용 동의(대표자 /대리인) 신설필요 | X35: =VLOOKUP(Y35,PC웹_서비스목록ID!$A$1:$E$111,2,FALSE) -> 0011 | Y35: 신청자 신용정보 조회 이용 동의(대표자 /대리인) 신설필요
J36: =VLOOKUP(K36,PC웹_서비스목록ID!$A$1:$E$111,2,FALSE) -> 0022 | K36: 결제일 | M36: =VLOOKUP(N36,PC웹_서비스목록ID!$A$1:$E$111,2,FALSE) -> 0016 | N36: 법인 정보 | P36: =VLOOKUP(Q36,PC웹_서비스목록ID!$A$1:$E$111,2,FALSE) -> 0037 | Q36: 개별카드 발급 대상 고객 정보- 개별 | R36: =VLOOKUP(S36,PC웹_서비스목록ID!$A$1:$E$111,2,FALSE) -> 0037 | S36: 개별카드 발급 대상 고객 정보- 개별 | V36: =VLOOKUP(W36,PC웹_서비스목록ID!$A$1:$E$111,2,FALSE) -> 0012 | W36: 신청인 본인인증 | X36: =VLOOKUP(Y36,PC웹_서비스목록ID!$A$1:$E$111,2,FALSE) -> 0012 | Y36: 신청인 본인인증
J37: =VLOOKUP(K37,PC웹_서비스목록ID!$A$1:$E$111,2,FALSE) -> 0023 | K37: 결제계좌 | M37: =VLOOKUP(N37,PC웹_서비스목록ID!$A$1:$E$111,2,FALSE) -> 0017 | N37: EDD정보 | P37: =VLOOKUP(Q37,PC웹_서비스목록ID!$A$1:$E$111,2,FALSE) -> 0044 | Q37: 개별카드 동의 조회(신청하기) - 개별_추가전용 | R37: =VLOOKUP(S37,PC웹_서비스목록ID!$A$1:$E$111,2,FALSE) -> 0044 | S37: 개별카드 동의 조회(신청하기) - 개별_추가전용 | V37: =VLOOKUP(W37,PC웹_서비스목록ID!$A$1:$E$111,2,FALSE) -> 0013 | W37: 신청인 CDD 조건부 검증(신설필요) | X37: =VLOOKUP(Y37,PC웹_서비스목록ID!$A$1:$E$111,2,FALSE) -> 0013 | Y37: 신청인 CDD 조건부 검증(신설필요)
J38: =VLOOKUP(K38,PC웹_서비스목록ID!$A$1:$E$111,2,FALSE) -> 0024 | K38: 신청매수 | M38: =VLOOKUP(N38,PC웹_서비스목록ID!$A$1:$E$111,2,FALSE) -> 0018 | N38: 필수확인사항 | P38: =VLOOKUP(Q38,PC웹_서비스목록ID!$A$1:$E$111,2,FALSE) -> 0039 | Q38: 개인신용정보 동의서 - 개별 | R38: =VLOOKUP(S38,PC웹_서비스목록ID!$A$1:$E$111,2,FALSE) -> 0039 | S38: 개인신용정보 동의서 - 개별 | V38: =VLOOKUP(W38,PC웹_서비스목록ID!$A$1:$E$111,2,FALSE) -> 0018 | W38: 필수확인사항 | X38: =VLOOKUP(Y38,PC웹_서비스목록ID!$A$1:$E$111,2,FALSE) -> 0047 | Y38: 대표자_사업자정보
J39: =VLOOKUP(K39,PC웹_서비스목록ID!$A$1:$E$111,2,FALSE) -> 0025 | K39: 발급 확인 및 약관수령 | M39: =VLOOKUP(N39,PC웹_서비스목록ID!$A$1:$E$111,2,FALSE) -> 0019 | N39: 이용한도 | P39: =VLOOKUP(Q39,PC웹_서비스목록ID!$A$1:$E$111,2,FALSE) -> 0040 | Q39: 개별카드 동의 조회(신청하기) - 개별 | R39: =VLOOKUP(S39,PC웹_서비스목록ID!$A$1:$E$111,2,FALSE) -> 0040 | S39: 개별카드 동의 조회(신청하기) - 개별 | V39: =VLOOKUP(W39,PC웹_서비스목록ID!$A$1:$E$111,2,FALSE) -> 0045 | W39: 기본정보 | X39: =VLOOKUP(Y39,PC웹_서비스목록ID!$A$1:$E$111,2,FALSE) -> 0048 | Y39: 업체(부서)정보
J40: =VLOOKUP(K40,PC웹_서비스목록ID!$A$1:$E$111,2,FALSE) -> 0026 | K40: 카드수령지 | M40: =VLOOKUP(N40,PC웹_서비스목록ID!$A$1:$E$111,2,FALSE) -> 0020 | N40: 명세서 받으실 곳 | P40: =VLOOKUP(Q40,PC웹_서비스목록ID!$A$1:$E$111,2,FALSE) -> 0046 | Q40: 유의 및 준비사항 | R40: =VLOOKUP(S40,PC웹_서비스목록ID!$A$1:$E$111,2,FALSE) -> 0046 | S40: 유의 및 준비사항 | V40: =VLOOKUP(W40,PC웹_서비스목록ID!$A$1:$E$111,2,FALSE) -> 0021 | W40: 카드선택 | X40: =VLOOKUP(Y40,PC웹_서비스목록ID!$A$1:$E$111,2,FALSE) -> 0018 | Y40: 필수확인사항
J41: =VLOOKUP(K41,PC웹_서비스목록ID!$A$1:$E$111,2,FALSE) -> 0027 | K41: 추천인 | M41: =VLOOKUP(N41,PC웹_서비스목록ID!$A$1:$E$111,2,FALSE) -> 0021 | N41: 카드선택 | P41: =VLOOKUP(Q41,PC웹_서비스목록ID!$A$1:$E$111,2,FALSE) -> 0005 | Q41: 제출서류 | R41: =VLOOKUP(S41,PC웹_서비스목록ID!$A$1:$E$111,2,FALSE) -> 0005 | S41: 제출서류 | V41: =VLOOKUP(W41,PC웹_서비스목록ID!$A$1:$E$111,2,FALSE) -> 0024 | W41: 신청매수 | X41: =VLOOKUP(Y41,PC웹_서비스목록ID!$A$1:$E$111,2,FALSE) -> 0050 | Y41: 부서별한도(요청한도 입력)
...

Sheet 분개 시점 처리계확인
A2: 처리 시점 | B2: 입력정보 | C2: 판단/조회 내용 | D2: 조치사항 | E2: 사유
A3: 상품선택(분개) | B3: 상품코드 | C3: - 상품 선택 시 "법인 크레딧 카드" 인경우 (플랫폼) | D3: 이메일 필수로 유효성 규칙 적용 | E3: 해당 카드는 제휴 카드이며 제휴 기관 채번 시 이메일 필수 값
A4: 신규_추가 팝업 창(분개) | B4: 사업자번호 | C4: ① 신규/추가 여부 판단(회원) ② 신용카드 발급 제한 여부 조회 판단(심사) ③ 최근 1개월 이내 동일 사유 반송건 심사 판단(심사) ④ 기본 회원 원장 정보 조회(추가 발급 선택시) | D4: ① 신규/추가 > 신규 또는 추가로 분개 ② 신용카드 발급 제한 > 제산 사유 시 접수 거절 ③ 최근 1개월 이내 동일 사유 반송건 2회 이상 존재 > 접수 거절 ④ 기본 회원 원장 정보 신청 페이지 반영(추가 발급 선택시 ) | E4: ① 신규/추가 여부 판단 ② 발급 불가 대상 고객 사전 접수 거절 민원 예방 ③ 발급 불가 대상 고객 사전 접수 거절 통한 민원 예방 ④ 추가 발급 회원의 경우 기존 정보를 이용한 빠른 발급
A5: 신청인 CDD 조건부 검증(신설필요) | B5: 신청인 주민번호 - 대표자 or 대리인 | C5: ① 신청인의 주민번호가 CDD 신규 또는 주기 초과 대상 판단(고객) | D5: ① 신청인의 주민번호가 CDD 신규 또는 주기 초과 대상은 > cdd 정보 수집 후 업데이트 실시 | E5: ① 신청인의 주민번호 CDD 업데이트 통한 법규 준수
A6: 신청인 CDD 조건부 검증(신설필요) | B6: 개별카드 주민번호 - 개별카드 | C6: ① 개별카드 소지자의 주민번호가 CDD 신규 또는 주기 초과 대상 판단(고객) | D6: ① 개별카드 소지자 주민번호가 CDD 신규 또는 주기 초과 대상은 > cdd 정보 수집 후 업데이트 실시 | E6: ① 개별카드 소지인 주민번호 CDD 업데이트 통한 법규 준수

Sheet 서비스목록ID (2)
A1: 화면기능목록 | B1: 기능록록 ID | C1: 법인사업자 | D1: 개인사업자 | E1: 화면기능목록 | F1: 고객 입렵값 | G1: 처리계 조회 | H1: 기능 정의 | I1: 기능 내용
A2: 사업자번호입력 | B2: 0001 | C2: Y | E2: 사업자번호입력 | F2: 사업자번호 | G2: N | H2: - 사업자 번호 조회를 통해 신규/추가 발급 여부를 구분함
A3: 신규 대상 통합 발급 안내 | B3: 0002 | C3: Y | E3: 신규 대상 통합 발급 안내 | F3: N | G3: 발급 유형 | H3: - 신규 발급 대상임을 안내함
A4: 추가 대상 통합 발급 안내 | B4: 0003 | C4: Y | E4: 추가 대상 통합 발급 안내 | F4: N | G4: 발급 유형 | H4: - 추가 발급 대상임을 안내함
A5: 준비사항 | B5: 0004 | C5: Y | E5: 준비사항 | F5: N | G5: N | H5: -단순 안내
A6: 제출서류 | B6: 0005 | C6: Y | E6: 제출서류 | F6: N | G6: N | H6: -단순 안내
A7: 서류자동제출서비스 | B7: 0006 | C7: Y | E7: 서류자동제출서비스 | F7: N | G7: N | H7: - 외부 서비스 Kodata를 이용하여 고객이 해당 사이트가 제공하는 제출 서류 대행 관련 WEb 서비스를 신청하고 복귀한다. [* 해당 서비스는 고객의 사업자등록증, 법인 전체 등기확인서를 고객을 대행하여 당사 서버로 제출해주는 서비스이며 , 배치 작업으로 당사 제공- 실시간 아님)
A8: 유의사항 | B8: 0007 | C8: Y | E8: 유의사항 | F8: N | G8: N | H8: ㅇ 단순 안내
A9: 법인 공동인증서(기업용)이용안내 | B9: 0008 | C9: Y | E9: 법인 공동인증서(기업용)이용안내 | F9: ㅇ 공용/개별 선택 | G9: N | H9: ㅇ 공용/개별카드의 분개가 발생한다.
A10: 신용카드 상품 약관동의 | B10: 0009 | C10: Y | E10: 신용카드 상품 약관동의 | F10: ㅇ 약관 동의 체크 | G10: N | H10: ㅇ 필수 동의로 동의 없이는 다음단계 진행 불가
A11: 신청인정보 | B11: 0010 | C11: Y | E11: 신청인정보 | F11: ㅇ 대표자 여부 ㅇ 신청인 성명 ㅇ 주민번호 ㅇ 휴대폰 번호 | G11: N
A12: 신청자 신용정보 조회 이용 동의(대표자 /대리인) 신설필요 | B12: 0011 | C12: Y | E12: 신청자 신용정보 조회 이용 동의(대표자 /대리인) 신설필요 | F12: N | G12: N | H12: ㅇ 동의 없이 다음 단계 진행이 불가하마
A13: 신청인 본인인증 | B13: 0012 | C13: Y | E13: 신청인 본인인증 | F13: ㅇ 인증방법에 따라 - 카드 번호 -휴대폰 번호 - 인증서 정보 를 고객이 선택하여 입력 | G13: ㅇ 고객 CDD 대상여부 검증후 대상 호가인 시 "신청인 CDD 조건부 검증(신설필요)" 항목으로 이동 | H13: ㅇ 신천인 본인인증 이며 인증방법은 3가지 이다
A14: 신청인 CDD 조건부 검증(신설필요) | B14: 0013 | C14: Y | E14: 신청인 CDD 조건부 검증(신설필요) | F14: - 고객식별은 주민번호 기준 ㅇ 신청인 성명 ㅇ 신청인 영문명 ㅇ 신청인 자택주수 ㅇ 신청인 신분증 정보 ㅇ 신청인 직업 ㅇ 신청인 직업 구분 상세 ㅇ 거래목적 ㅇ 거래자금 원천 | G14: ㅇ 고객 CDD 대상여부 | H14: ㅇ 모든 항목이 필수값이며 Null로 진행이 불가하다. ㅇ 미입력 시 > ㅇㅇㅇ 값을 선택해 주세요로 에러 처리
A15: 대표자 정보 | B15: 0014 | C15: Y | E15: 대표자 정보 | F15: ㅇ 대표자 성명 ㅇ 대표자 영문성명 | G15: N | H15: ㅇ 모든 항목이 필수값이며 Null로 진행이 불가하다. 영 미입력 시 > ㅇㅇㅇ 값을 선택해 주세요로 에러 처리
A16: 사업자 정보 | B16: 0015 | C16: Y | E16: 사업자 정보 | F16: ㅇ 사업자번호는 전 세션에 서 가져다 붙이기 ㅇ 업체명 ㅇ 업체 영문명 ㅇ 전화번호 ㅇ 주소 ㅇ 설립일 | G16: N | H16: ㅇ 사업자 번호는 전세션에서 가지고 온다
A17: 법인 정보 | B17: 0016 | C17: Y | E17: 법인 정보 | F17: ㅇ 법인등록번호 ㅇ 법인명 ㅇ 전화번호 ㅇ 주소 는 고객입력 - 법인명 사업자 명에서 그대로 붙이기 - 전화번호 , 주소소 '사업자 정보'에서 가져다 붙이기 | G17: N | H17: 법인명 모든 항목이 필수값이며 Null로 진행이 불가하다. ㅇ 미입력 시 > ㅇㅇ법인명 ㅇ 값을 선택해 주세요로 에러 처리
A18: EDD정보 | B18: 0017 | C18: Y | E18: EDD정보 | F18: - 사업자기준임 ㅇ 거래 목적 ㅇ 거래자금의 원천 | G18: N | H18: ㅇ 고객 입력값
A19: 필수확인사항 | B19: 0018 | C19: Y | E19: 필수확인사항 | F19: ㅇ 별도 유효성 체크 로직 | G19: N | H19: ㅇ 기존 가능 결제일 선택 범위 확인 필요 > 플랫폼 개발 부 요건 확인 ㅇ 별도 유효성 체크로직 플랫폼 개발부 확인 요
A20: 이용한도 | B20: 0019 | C20: Y | E20: 이용한도 | F20: ㅇ 이용한도 | G20: N | H20: ㅇ 이용한도는 10만원 단위로 입력한다
A21: 명세서 받으실 곳 | B21: 0020 | C21: Y | E21: 명세서 받으실 곳 | F21: ㅇ 이메일, app, 우편중 선택 ㅇ 수령 방법이 이메일인 경우 또는 특정상품코드(기업 크레딧 계열) 인 경우 이메일이 필수 | G21: N | H21: ㅇ 명세서 받으실 곳 선택
A22: 카드선택 | B22: 0021 | C22: Y | E22: 카드선택 | F22: ㅇ 브랜드 선택 : 3중 택일 | G22: N | H22: ㅇ 카드 선택 시 - 국내 전용 선택시는 해외원화결제 차당 서비스 disable
A23: 결제일 | B23: 0022 | C23: Y | E23: 결제일 | F23: ㅇ "필수확인사항" 에서 가져옴 ㅇ "필수확인사항'에서 가져온 경우 disable. | G23: N | H23: ㅇ 기존 가능 결제일 선택 범위 확인 필요 > 플랫폼 개발 부 요건 확인
... A25: 신청매수 | B25: 0024 | C25: Y | E25: 신청매수 | F25: ㅇ 공용카드 신청매수 ㅇ 개별카드는 신청매수 항목없음 | G25: N | H25: ㅇ 신청매수를 입력 받음 , 최대 매수 기존과 동일
A26: 발급 확인 및 약관수령 | B26: 0025 | C26: Y | E26: 발급 확인 및 약관수령 | F26: ㅇ 약관 수령 방법 선택 ㅇ 이메일 선택시 이메일 필수 | H26: ㅇ 고개입력값
A27: 카드수령지 | B27: 0026 | C27: Y | E27: 카드수령지 | F27: ㅇ 카드 수령지 , 수령동의 고객 입력 ㅇ 수령인 정보는 신청자 정보에서 가져오며 disable. | H27: 서비스목록!A1
A28: 추천인 | B28: 0027 | C28: Y | E28: 추천인 | F28: ㅇ 권유자 유형코드 입력 | G28: ㅇ 권유자 정보 DB는 처리계에서 조회 - 고객/공통 영역
A29: 공동인증서 인증 | B29: 0028 | C29: Y | E29: 공동인증서 인증 | F29: ㅇ인증서 | G29: N | H29: ㅇ 공인인증
A30: 카드정보(확인용) | B30: 0029 | C30: Y | E30: 카드정보(확인용) | F30: N | G30: N | H30: ㅇ 단순 정보성 조회
A31: 사업자정보(확인용) | B31: 0030 | C31: Y | E31: 사업자정보(확인용) | F31: N | G31: N | H31: ㅇ 단순 정보성 조회
A32: 대표자정보(확인용) | B32: 0031 | C32: Y | E32: 대표자정보(확인용) | F32: N | G32: N | H32: ㅇ 단순 정보성 조회
A33: 법인인증 | B33: 0032 | C33: Y | E33: 법인인증 | F33: ㅇ 대표자의 휴대폰 본인 인증 또는 법인인감즈명서 파일 업로드 | G33: N | H33: ㅇ 대표자의 휴대폰 본인 인증 또는 법인인감증명서 파일 업로드 중 한가지의 형태로 인증한다
A34: 추가서류제출 | B34: 0033 | C34: Y | E34: 추가서류제출 | F34: ㅇ 사업자등록증 ㅇ 법인등기부 ㅇ 주주명부 및 정관 ㅇ 신청인 신분증 은 필수 상기 위외 항목은 ㅇ 선택으로 제공받는다. ㅇ 업로드 파일 형식은 PDF , 그림(jpg, png,tff 등을 허용한다) ㅇ 수정하기를 허용하고 > 수정하기 버튼을 누르면 "명세서 받으실 곳(ID:0020)"으로 간다 | G34: N | H34: ㅇ 필수 항목은 반드시 받아야 다음으로 넘어간다
A35: 신청완료 | B35: 0034 | C35: Y | E35: 신청완료 | F35: N | G35: N | H35: ㅇ 단순 정보성 조회
A36: 개별 카드 회원 동의서 작성안내 | B36: 0035 | C36: Y | E36: 개별 카드 회원 동의서 작성안내 | F36: N | G36: N
A37: 개별카드 사용자 개인명의계좌 등록- 개별 | B37: 0036 | C37: Y | E37: 개별카드 사용자 개인명의계좌 등록- 개별 | F37: ㅇ 개별신청 고객의 경우 해당 고객의 결제 계좌를 등록 필요 ㅇ 해당 고객이 개인명의 계좌 등록안내에 동의한 경우 실시간으로 LMS 발송 함 ㅇ LMS 발송을 통한 "결제 계좌 등록 프로세스 "가 별도 있으나 작동 점검 필요 | G37: ㅇ LMS 발송 관련 처리계 거래 호출할 것으로 판단됨 > 어떤 거래 호출해서 LMS 보내는지 플랫폼에 Q&A필요 | H37: 경우 모든 항목이 필수값이며 Null로 진행이 불가하다.당 고객의 결제 계좌를 등록 필요 ㅇ 미입력 시 > ㅇㅇ경우 값을 선택해 주세요로 에러 처리
A38: 개별카드 발급 대상 고객 정보- 개별 | B38: 0037 | C38: Y | E38: 개별카드 발급 대상 고객 정보- 개별 | F38: ㅇ 개별카드 대상자의 정보 입력 - 성명 - 주민번호 - 휴대폰번호 ㅇ 필수동의서 작성 요청 하기 LMS 발송 기능 필요 | G38: ㅇ LMS 발송 관련 처리계 거래 호출할 것으로 판단됨 > 어떤 거래 호출해서 LMS 보내는지 플랫폼에 Q&A필요 | H38: 정보 모든 항목이 필수값이며 Null로 진행이 불가하다.입력 미입력 시 > ㅇㅇ정보 값을 선택해 주세요로 에러 처리
A39: 개별카드 동의 조회(조회하기)- 개별 | B39: 0038 | C39: Y | E39: 개별카드 동의 조회(조회하기)- 개별 | F39: N | G39: ㅇ 고객이 새로 고침을 눌렀을때 동의서 작성 여부 값 체크 > 개별카드 동의서 작성 여부를 플랫폼 내 저장한 DB를 참조하는 지 처리계 거래를 참조하는 지 플랫폼개발부 확인필요 | H39: ㅇ 고객이 새로 고침을 눌렀을때 동의서 작성 여부 값 체크 ㅇ 동의서 작성 시 "동의서 작성 재요청하기" 버튼을 > "카드신청하기" 버튼으로 변경함 ㅇ "카드신청하기 " 버튼 클릭시 카드 신청 프로세스 재개함
A40: 개인신용정보 동의서 - 개별 | B40: 0039 | C40: Y | E40: 개인신용정보 동의서 - 개별 | F40: ㅇ 버튼클릭 | G40: ㅇ 동의 정보를 플랫폼 내부에 저장하는지 , 처리계 거래를 호출하는 지 플랫폼 개발부에 확인 필요 | H40: ㅇ 본인인증 선택시 "신청인 본인인증" (ID:0012)절차 진행
A41: 개별카드 동의 조회(신청하기) - 개별 | B41: 0040 | C41: Y | E41: 개별카드 동의 조회(신청하기) - 개별 | F41: ㅇ 버튼클릭 | G41: N | H41: ㅇ 시청하기 버튼 클릭 시 카드 발급 신청 시나리오 재개
...

Sheet 법사자_체크
A1: 분개 시점 | B1: 시나리오수
A2: 체크 | B2: 1 | P2: 체크
P3: 상품선택(분개)
O4: =VLOOKUP(P4,PC웹_서비스목록ID!$A$1:$E$111,2,FALSE) -> 0001 | P4: 사업자번호입력
O5: =VLOOKUP(P5,PC웹_서비스목록ID!$A$1:$E$111,2,FALSE) -> 0002 | P5: 신규 대상 통합 발급 안내
P7: 신규_추가 팝업 창(분개)
A8: 신규/추가 | B8: 2 | O8: 체크_신규 분개 | Q8: 체크_추가 분개
N9: =VLOOKUP(O9,PC웹_서비스목록ID!$A$1:$E$111,2,FALSE) -> 0002 | O9: 신규 대상 통합 발급 안내 | P9: =VLOOKUP(Q9,PC웹_서비스목록ID!$A$1:$E$111,2,FALSE) -> 0003 | Q9: 추가 대상 통합 발급 안내
N10: =VLOOKUP(O10,PC웹_서비스목록ID!$A$1:$E$111,2,FALSE) -> 0004 | O10: 준비사항 | P10: =VLOOKUP(Q10,PC웹_서비스목록ID!$A$1:$E$111,2,FALSE) -> 0004 | Q10: 준비사항
N11: =VLOOKUP(O11,PC웹_서비스목록ID!$A$1:$E$111,2,FALSE) -> 0005 | O11: 제출서류 | P11: =VLOOKUP(Q11,PC웹_서비스목록ID!$A$1:$E$111,2,FALSE) -> 0005 | Q11: 제출서류
N12: =VLOOKUP(O12,PC웹_서비스목록ID!$A$1:$E$111,2,FALSE) -> 0006 | O12: 서류자동제출서비스 | P12: =VLOOKUP(Q12,PC웹_서비스목록ID!$A$1:$E$111,2,FALSE) -> 0006 | Q12: 서류자동제출서비스
N13: =VLOOKUP(O13,PC웹_서비스목록ID!$A$1:$E$111,2,FALSE) -> 0007 | O13: 유의사항 | P13: =VLOOKUP(Q13,PC웹_서비스목록ID!$A$1:$E$111,2,FALSE) -> 0007 | Q13: 유의사항
N14: =VLOOKUP(O14,PC웹_서비스목록ID!$A$1:$E$111,2,FALSE) -> 0008 | O14: 법인 공동인증서(기업용)이용안내 | P14: =VLOOKUP(Q14,PC웹_서비스목록ID!$A$1:$E$111,2,FALSE) -> 0008 | Q14: 법인 공동인증서(기업용)이용안내
O15: 공용/개별 팝업창(분개) | Q15: 공용/개별 팝업창 (분개)
O16: -
O17: -
O18: -
O19: -
O20: -
O21: -
A22: 개별/공용 | B22: 3 | K22: 체크_신규_공용 분개_대표 OR 대리인 | N22: 체크_신규_개별 분개_대표 OR 대리인 | R22: 체크_추가_개별 분개 | X22: 체크_추가_공용 분개
J23: =VLOOKUP(K23,PC웹_서비스목록ID!$A$1:$E$111,2,FALSE) -> #N/A | K23: 체크카드 상품 약관동의 | M23: =VLOOKUP(N23,PC웹_서비스목록ID!$A$1:$E$111,2,FALSE) -> #N/A | N23: 체크카드 상품 약관동의 | R23: - | W23: =VLOOKUP(X23,PC웹_서비스목록ID!$A$1:$E$111,2,FALSE) -> #N/A | X23: 체크카드 상품 약관동의
J24: =VLOOKUP(K24,PC웹_서비스목록ID!$A$1:$E$111,2,FALSE) -> 0010 | K24: 신청인정보 | M24: =VLOOKUP(N24,PC웹_서비스목록ID!$A$1:$E$111,2,FALSE) -> 0035 | N24: 개별 카드 회원 동의서 작성안내 | O24: 신청인 CDD 조건부 검증(신설필요) | Q24: =VLOOKUP(R24,PC웹_서비스목록ID!$A$1:$E$111,2,FALSE) -> #N/A | R24: 발급 대상 분서 팝업(신설필요) | W24: =VLOOKUP(X24,PC웹_서비스목록ID!$A$1:$E$111,2,FALSE) -> #N/A | X24: 발급 대상 분서 팝업(신설필요)
J25: =VLOOKUP(K25,PC웹_서비스목록ID!$A$1:$E$111,2,FALSE) -> #N/A | K25: 신청자 체크정보 조회 이용 동의(대표자 /대리인) 신설필요 | M25: =VLOOKUP(N25,PC웹_서비스목록ID!$A$1:$E$111,2,FALSE) -> 0036 | N25: 개별카드 사용자 개인명의계좌 등록- 개별 | R25: 발급대상부서 분개 발생 | W25: =VLOOKUP(X25,PC웹_서비스목록ID!$A$1:$E$111,2,FALSE) -> #N/A | X25: 부서내 추가발급_부서추가 분개
J26: =VLOOKUP(K26,PC웹_서비스목록ID!$A$1:$E$111,2,FALSE) -> 0012 | K26: 신청인 본인인증 | M26: =VLOOKUP(N26,PC웹_서비스목록ID!$A$1:$E$111,2,FALSE) -> 0037 | N26: 개별카드 발급 대상 고객 정보- 개별
J27: =VLOOKUP(K27,PC웹_서비스목록ID!$A$1:$E$111,2,FALSE) -> 0013 | K27: 신청인 CDD 조건부 검증(신설필요) | M27: =VLOOKUP(N27,PC웹_서비스목록ID!$A$1:$E$111,2,FALSE) -> 0038 | N27: 개별카드 동의 조회(조회하기)- 개별
J28: =VLOOKUP(K28,PC웹_서비스목록ID!$A$1:$E$111,2,FALSE) -> 0014 | K28: 대표자 정보 | M28: =VLOOKUP(N28,PC웹_서비스목록ID!$A$1:$E$111,2,FALSE) -> #N/A | N28: 개인체크정보 동의서 - 개별
J29: =VLOOKUP(K29,PC웹_서비스목록ID!$A$1:$E$111,2,FALSE) -> 0015 | K29: 사업자 정보 | M29: =VLOOKUP(N29,PC웹_서비스목록ID!$A$1:$E$111,2,FALSE) -> 0040 | N29: 개별카드 동의 조회(신청하기) - 개별
J30: =VLOOKUP(K30,PC웹_서비스목록ID!$A$1:$E$111,2,FALSE) -> 0016 | K30: 법인 정보 | M30: =VLOOKUP(N30,PC웹_서비스목록ID!$A$1:$E$111,2,FALSE) -> 0010 | N30: 신청인정보
J31: =VLOOKUP(K31,PC웹_서비스목록ID!$A$1:$E$111,2,FALSE) -> 0017 | K31: EDD정보 | M31: =VLOOKUP(N31,PC웹_서비스목록ID!$A$1:$E$111,2,FALSE) -> #N/A | N31: 신청자 체크정보 조회 이용 동의(대표자 /대리인) 신설필요
J32: =VLOOKUP(K32,PC웹_서비스목록ID!$A$1:$E$111,2,FALSE) -> #N/A | K32: - | M32: =VLOOKUP(N32,PC웹_서비스목록ID!$A$1:$E$111,2,FALSE) -> 0012 | N32: 신청인 본인인증
A33: 부서내추가/부서부가 | J33: =VLOOKUP(K33,PC웹_서비스목록ID!$A$1:$E$111,2,FALSE) -> #N/A | K33: - | M33: =VLOOKUP(N33,PC웹_서비스목록ID!$A$1:$E$111,2,FALSE) -> 0013 | N33: 신청인 CDD 조건부 검증(신설필요) | Q33: 체크_추가_개별_부서내 추가발급 분개 | S33: 체크_추가_개별_부서 추가 분개 | W33: 체크_추가_공용_부서내 추가발급 분개 | Y33: 체크_추가공용_부서 추가 분개
J34: =VLOOKUP(K34,PC웹_서비스목록ID!$A$1:$E$111,2,FALSE) -> 0020 | K34: 명세서 받으실 곳 | M34: =VLOOKUP(N34,PC웹_서비스목록ID!$A$1:$E$111,2,FALSE) -> 0014 | N34: 대표자 정보 | P34: =VLOOKUP(Q34,PC웹_서비스목록ID!$A$1:$E$111,2,FALSE) -> 0035 | Q34: 개별 카드 회원 동의서 작성안내 | R34: =VLOOKUP(S34,PC웹_서비스목록ID!$A$1:$E$111,2,FALSE) -> 0035 | S34: 개별 카드 회원 동의서 작성안내 | V34: =VLOOKUP(W34,PC웹_서비스목록ID!$A$1:$E$111,2,FALSE) -> 0010 | W34: 신청인정보 | X34: =VLOOKUP(Y34,PC웹_서비스목록ID!$A$1:$E$111,2,FALSE) -> 0010 | Y34: 신청인정보
J35: =VLOOKUP(K35,PC웹_서비스목록ID!$A$1:$E$111,2,FALSE) -> 0021 | K35: 카드선택 | M35: =VLOOKUP(N35,PC웹_서비스목록ID!$A$1:$E$111,2,FALSE) -> 0015 | N35: 사업자 정보 | P35: =VLOOKUP(Q35,PC웹_서비스목록ID!$A$1:$E$111,2,FALSE) -> 0036 | Q35: 개별카드 사용자 개인명의계좌 등록- 개별 | R35: =VLOOKUP(S35,PC웹_서비스목록ID!$A$1:$E$111,2,FALSE) -> 0036 | S35: 개별카드 사용자 개인명의계좌 등록- 개별 | V35: =VLOOKUP(W35,PC웹_서비스목록ID!$A$1:$E$111,2,FALSE) -> #N/A | W35: 신청자 체크정보 조회 이용 동의(대표자 /대리인) 신설필요 | X35: =VLOOKUP(Y35,PC웹_서비스목록ID!$A$1:$E$111,2,FALSE) -> #N/A | Y35: 신청자 체크정보 조회 이용 동의(대표자 /대리인) 신설필요
J36: =VLOOKUP(K36,PC웹_서비스목록ID!$A$1:$E$111,2,FALSE) -> 0022 | K36: 결제일 | M36: =VLOOKUP(N36,PC웹_서비스목록ID!$A$1:$E$111,2,FALSE) -> 0016 | N36: 법인 정보 | P36: =VLOOKUP(Q36,PC웹_서비스목록ID!$A$1:$E$111,2,FALSE) -> 0037 | Q36: 개별카드 발급 대상 고객 정보- 개별 | R36: =VLOOKUP(S36,PC웹_서비스목록ID!$A$1:$E$111,2,FALSE) -> 0037 | S36: 개별카드 발급 대상 고객 정보- 개별 | V36: =VLOOKUP(W36,PC웹_서비스목록ID!$A$1:$E$111,2,FALSE) -> 0012 | W36: 신청인 본인인증 | X36: =VLOOKUP(Y36,PC웹_서비스목록ID!$A$1:$E$111,2,FALSE) -> 0012 | Y36: 신청인 본인인증
J37: =VLOOKUP(K37,PC웹_서비스목록ID!$A$1:$E$111,2,FALSE) -> 0023 | K37: 결제계좌 | M37: =VLOOKUP(N37,PC웹_서비스목록ID!$A$1:$E$111,2,FALSE) -> 0017 | N37: EDD정보 | P37: =VLOOKUP(Q37,PC웹_서비스목록ID!$A$1:$E$111,2,FALSE) -> 0044 | Q37: 개별카드 동의 조회(신청하기) - 개별_추가전용 | R37: =VLOOKUP(S37,PC웹_서비스목록ID!$A$1:$E$111,2,FALSE) -> 0044 | S37: 개별카드 동의 조회(신청하기) - 개별_추가전용 | V37: =VLOOKUP(W37,PC웹_서비스목록ID!$A$1:$E$111,2,FALSE) -> 0013 | W37: 신청인 CDD 조건부 검증(신설필요) | X37: =VLOOKUP(Y37,PC웹_서비스목록ID!$A$1:$E$111,2,FALSE) -> 0013 | Y37: 신청인 CDD 조건부 검증(신설필요)
J38: =VLOOKUP(K38,PC웹_서비스목록ID!$A$1:$E$111,2,FALSE) -> 0024 | K38: 신청매수 | M38: =VLOOKUP(N38,PC웹_서비스목록ID!$A$1:$E$111,2,FALSE) -> #N/A | N38: - | P38: =VLOOKUP(Q38,PC웹_서비스목록ID!$A$1:$E$111,2,FALSE) -> 0039 | Q38: 개인신용정보 동의서 - 개별 | R38: =VLOOKUP(S38,PC웹_서비스목록ID!$A$1:$E$111,2,FALSE) -> 0039 | S38: 개인신용정보 동의서 - 개별 | V38: =VLOOKUP(W38,PC웹_서비스목록ID!$A$1:$E$111,2,FALSE) -> #N/A | W38: - | X38: =VLOOKUP(Y38,PC웹_서비스목록ID!$A$1:$E$111,2,FALSE) -> 0047 | Y38: 대표자_사업자정보
J39: =VLOOKUP(K39,PC웹_서비스목록ID!$A$1:$E$111,2,FALSE) -> 0025 | K39: 발급 확인 및 약관수령 | M39: =VLOOKUP(N39,PC웹_서비스목록ID!$A$1:$E$111,2,FALSE) -> #N/A | N39: - | P39: =VLOOKUP(Q39,PC웹_서비스목록ID!$A$1:$E$111,2,FALSE) -> 0040 | Q39: 개별카드 동의 조회(신청하기) - 개별 | R39: =VLOOKUP(S39,PC웹_서비스목록ID!$A$1:$E$111,2,FALSE) -> 0040 | S39: 개별카드 동의 조회(신청하기) - 개별 | V39: =VLOOKUP(W39,PC웹_서비스목록ID!$A$1:$E$111,2,FALSE) -> 0045 | W39: 기본정보 | X39: =VLOOKUP(Y39,PC웹_서비스목록ID!$A$1:$E$111,2,FALSE) -> 0048 | Y39: 업체(부서)정보
J40: =VLOOKUP(K40,PC웹_서비스목록ID!$A$1:$E$111,2,FALSE) -> 0026 | K40: 카드수령지 | M40: =VLOOKUP(N40,PC웹_서비스목록ID!$A$1:$E$111,2,FALSE) -> 0020 | N40: 명세서 받으실 곳 | P40: =VLOOKUP(Q40,PC웹_서비스목록ID!$A$1:$E$111,2,FALSE) -> 0046 | Q40: 유의 및 준비사항 | R40: =VLOOKUP(S40,PC웹_서비스목록ID!$A$1:$E$111,2,FALSE) -> 0046 | S40: 유의 및 준비사항 | V40: =VLOOKUP(W40,PC웹_서비스목록ID!$A$1:$E$111,2,FALSE) -> 0021 | W40: 카드선택 | X40: =VLOOKUP(Y40,PC웹_서비스목록ID!$A$1:$E$111,2,FALSE) -> #N/A | Y40: -
J41: =VLOOKUP(K41,PC웹_서비스목록ID!$A$1:$E$111,2,FALSE) -> 0027 | K41: 추천인 | M41: =VLOOKUP(N41,PC웹_서비스목록ID!$A$1:$E$111,2,FALSE) -> 0021 | N41: 카드선택 | P41: =VLOOKUP(Q41,PC웹_서비스목록ID!$A$1:$E$111,2,FALSE) -> 0005 | Q41: 제출서류 | R41: =VLOOKUP(S41,PC웹_서비스목록ID!$A$1:$E$111,2,FALSE) -> 0005 | S41: 제출서류 | V41: =VLOOKUP(W41,PC웹_서비스목록ID!$A$1:$E$111,2,FALSE) -> 0024 | W41: 신청매수 | X41: =VLOOKUP(Y41,PC웹_서비스목록ID!$A$1:$E$111,2,FALSE) -> 0050 | Y41: 부서별한도(요청한도 입력)
...

Sheet 개사자_신용
A1: 분개 시점 | B1: 시나리오수
A2: 신용 | B2: 1 | P2: 신용
P3: 상품선택(분개)
O4: =VLOOKUP(P4,PC웹_서비스목록ID!$A$1:$E$111,2,FALSE) -> 0001 | P4: 사업자번호입력
P7: 신규_추가 팝업 창(분개)
A8: 신규/추가 | B8: 2 | O8: 신용_신규 분개 | Q8: 신용_추가 분개
N9: =VLOOKUP(O9,PC웹_서비스목록ID!$A$1:$E$111,2,FALSE) -> 0002 | O9: 신규 대상 통합 발급 안내 | P9: =VLOOKUP(Q9,PC웹_서비스목록ID!$A$1:$E$111,2,FALSE) -> 0003 | Q9: 추가 대상 통합 발급 안내
N10: =VLOOKUP(O10,PC웹_서비스목록ID!$A$1:$E$111,2,FALSE) -> 0053 | O10: 유의 및 준비사항(개사자_신용) | P10: =VLOOKUP(Q10,PC웹_서비스목록ID!$A$1:$E$111,2,FALSE) -> 0053 | Q10: 유의 및 준비사항(개사자_신용)
N11: =VLOOKUP(O11,PC웹_서비스목록ID!$A$1:$E$111,2,FALSE) -> 0054 | O11: 추가정보선택(개사자전용) | P11: =VLOOKUP(Q11,PC웹_서비스목록ID!$A$1:$E$111,2,FALSE) -> 0054 | Q11: 추가정보선택(개사자전용)
N12: =VLOOKUP(O12,PC웹_서비스목록ID!$A$1:$E$111,2,FALSE) -> 0055 | O12: 약관동의(신용 or 체크) | P12: =VLOOKUP(Q12,PC웹_서비스목록ID!$A$1:$E$111,2,FALSE) -> 0055 | Q12: 약관동의(신용 or 체크)
N13: =VLOOKUP(O13,PC웹_서비스목록ID!$A$1:$E$111,2,FALSE) -> 0057 | O13: 카드신청 기본_CDD(개사자전용) | P13: =VLOOKUP(Q13,PC웹_서비스목록ID!$A$1:$E$111,2,FALSE) -> 0057 | Q13: 카드신청 기본_CDD(개사자전용)
N14: =VLOOKUP(O14,PC웹_서비스목록ID!$A$1:$E$111,2,FALSE) -> 0058 | O14: 3종 본인인증(개사자_신용_체크) | P14: =VLOOKUP(Q14,PC웹_서비스목록ID!$A$1:$E$111,2,FALSE) -> 0058 | Q14: 3종 본인인증(개사자_신용_체크)
N15: =VLOOKUP(O15,PC웹_서비스목록ID!$A$1:$E$111,2,FALSE) -> 0059 | O15: 설립년월일_업종분류(개사자전용) | P15: =VLOOKUP(Q15,PC웹_서비스목록ID!$A$1:$E$111,2,FALSE) -> 0059 | Q15: 설립년월일_업종분류(개사자전용)
N16: =VLOOKUP(Q16,PC웹_서비스목록ID!$A$1:$E$111,2,FALSE) -> 0060 | O16: 한도부여결과조회(개사자전용) | P16: =VLOOKUP(Q16,PC웹_서비스목록ID!$A$1:$E$111,2,FALSE) -> 0060 | Q16: 한도부여결과조회(개사자전용)
N17: =VLOOKUP(O17,PC웹_서비스목록ID!$A$1:$E$111,2,FALSE) -> 0061 | O17: 신분증 정보(개사자전용) | P17: =VLOOKUP(Q17,PC웹_서비스목록ID!$A$1:$E$111,2,FALSE) -> 0061 | Q17: 신분증 정보(개사자전용)
N18: =VLOOKUP(O18,PC웹_서비스목록ID!$A$1:$E$111,2,FALSE) -> 0062 | O18: 필수확인사항(개사자전용) | P18: =VLOOKUP(Q18,PC웹_서비스목록ID!$A$1:$E$111,2,FALSE) -> 0062 | Q18: 필수확인사항(개사자전용)
N19: =VLOOKUP(O19,PC웹_서비스목록ID!$A$1:$E$111,2,FALSE) -> 0063 | O19: 카드정보(개사자전용) | P19: =VLOOKUP(Q19,PC웹_서비스목록ID!$A$1:$E$111,2,FALSE) -> 0063 | Q19: 카드정보(개사자전용)
N20: =VLOOKUP(O20,PC웹_서비스목록ID!$A$1:$E$111,2,FALSE) -> 0064 | O20: 카드정보수정하기(개사자전용) | P20: =VLOOKUP(Q20,PC웹_서비스목록ID!$A$1:$E$111,2,FALSE) -> 0064 | Q20: 카드정보수정하기(개사자전용)
N21: =VLOOKUP(O21,PC웹_서비스목록ID!$A$1:$E$111,2,FALSE) -> #N/A | O21: 필수 항목 활영(이미지 접수) | P21: =VLOOKUP(Q21,PC웹_서비스목록ID!$A$1:$E$111,2,FALSE) -> #N/A | Q21: 필수 항목 촬용
N22: =VLOOKUP(O22,PC웹_서비스목록ID!$A$1:$E$111,2,FALSE) -> 0065 | O22: 카드신청완료(개사자전용) | P22: =VLOOKUP(Q22,PC웹_서비스목록ID!$A$1:$E$111,2,FALSE) -> 0065 | Q22: 카드신청완료(개사자전용)

Sheet 개사자_체크
A1: 분개 시점 | B1: 시나리오수
A2: 신용 | B2: 1 | P2: 신용
P3: 상품선택(분개)
O4: =VLOOKUP(P4,PC웹_서비스목록ID!$A$1:$E$111,2,FALSE) -> 0001 | P4: 사업자번호입력
P7: 신규_추가 팝업 창(분개)
A8: 신규/추가 | B8: 2 | O8: 체크_신규 분개(검증완료) | Q8: 체크_신규 분개(검증필요)
P9: =VLOOKUP(Q9,PC웹_서비스목록ID!$A$1:$E$111,2,FALSE) -> #N/A
N10: =VLOOKUP(O10,PC웹_서비스목록ID!$A$1:$E$111,2,FALSE) -> 0066 | O10: 유의 및 준비사항(개사_체크전용) | P10: =VLOOKUP(Q10,PC웹_서비스목록ID!$A$1:$E$111,2,FALSE) -> 0066 | Q10: 유의 및 준비사항(개사_체크전용)
N11: =VLOOKUP(O11,PC웹_서비스목록ID!$A$1:$E$111,2,FALSE) -> 0067 | O11: 신분증진위확인_촬영 또는 직접 입력 선택(개사자_체크) | P11: =VLOOKUP(Q11,PC웹_서비스목록ID!$A$1:$E$111,2,FALSE) -> 0067 | Q11: 신분증진위확인_촬영 또는 직접 입력 선택(개사자_체크)
N12: =VLOOKUP(O12,PC웹_서비스목록ID!$A$1:$E$111,2,FALSE) -> 0068 | O12: 신분증정보 입력(개사 체크) | P12: =VLOOKUP(Q12,PC웹_서비스목록ID!$A$1:$E$111,2,FALSE) -> 0068 | Q12: 신분증정보 입력(개사 체크)
N13: =VLOOKUP(O13,PC웹_서비스목록ID!$A$1:$E$111,2,FALSE) -> 0069 | O13: 본인확인(개사_체크) | P13: =VLOOKUP(Q13,PC웹_서비스목록ID!$A$1:$E$111,2,FALSE) -> 0069 | Q13: 본인확인(개사_체크)
N14: =VLOOKUP(O14,PC웹_서비스목록ID!$A$1:$E$111,2,FALSE) -> 0058 | O14: 3종 본인인증(개사자_신용_체크) | P14: =VLOOKUP(Q14,PC웹_서비스목록ID!$A$1:$E$111,2,FALSE) -> 0058 | Q14: 3종 본인인증(개사자_신용_체크)
N15: =VLOOKUP(O15,PC웹_서비스목록ID!$A$1:$E$111,2,FALSE) -> 0070 | O15: 신청정보_CDD(개사_체크) | P15: =VLOOKUP(Q15,PC웹_서비스목록ID!$A$1:$E$111,2,FALSE) -> 0070 | Q15: 신청정보_CDD(개사_체크)
N16: =VLOOKUP(O16,PC웹_서비스목록ID!$A$1:$E$111,2,FALSE) -> 0071 | O16: 신청정보_설립년월(개사_체크) | P16: =VLOOKUP(Q16,PC웹_서비스목록ID!$A$1:$E$111,2,FALSE) -> 0071 | Q16: 신청정보_설립년월(개사_체크) | R16: 추가도 계좌 정보가 필요한가 ? 체크
N17: =VLOOKUP(O17,PC웹_서비스목록ID!$A$1:$E$111,2,FALSE) -> 0072 | O17: 약관동의(개사자_체크) | P17: =VLOOKUP(Q17,PC웹_서비스목록ID!$A$1:$E$111,2,FALSE) -> 0072 | Q17: 약관동의(개사자_체크)
N18: =VLOOKUP(O18,PC웹_서비스목록ID!$A$1:$E$111,2,FALSE) -> 0073 | O18: 신청정보_수정하기(개사자_체크) | P18: =VLOOKUP(Q18,PC웹_서비스목록ID!$A$1:$E$111,2,FALSE) -> 0073 | Q18: 신청정보_수정하기(개사자_체크)
N19: =VLOOKUP(O19,PC웹_서비스목록ID!$A$1:$E$111,2,FALSE) -> 0074 | O19: 접수완료(개사자_체크) | P19: =VLOOKUP(Q19,PC웹_서비스목록ID!$A$1:$E$111,2,FALSE) -> 0074 | Q19: 접수완료(개사자_체크)
N20: =VLOOKUP(O20,PC웹_서비스목록ID!$A$1:$E$111,2,FALSE) -> #N/A

Sheet PC웹_서비스목록ID
A1: 화면기능목록 | B1: 기능록록 ID | C1: 법인사업자 | D1: 개인사업자 | E1: 화면기능목록 | F1: Action | G1: 입력값 형태 | H1: 처리계 거래 | I1: 처리계 거래 목적 | J1: 목적 | K1: 기능 내용(법사자 PC웹) | L1: 기능 내용(개사자 mobile Web)
A2: 사업자번호입력 | B2: 0001 | C2: Y | D2: N | E2: 사업자번호입력 | F2: 정보입력 | G2: 사업자번호 | H2: 회원 | I2: 발급유형 | J2: 신규/추가 발급 대상 여부를 처리계 조회
A3: 신규 대상 통합 발급 안내 | B3: 0002 | C3: Y | D3: N | E3: 신규 대상 통합 발급 안내 | F3: 조회 결과 안내 | G3: N | H3: 회원 | I3: 발급유현판단 | J3: 신규 발급 대상 여부를 처리계 조회하여 고객앞 안내 | L3: 추가 필요
A4: 추가 대상 통합 발급 안내 | B4: 0003 | C4: Y | D4: N | E4: 추가 대상 통합 발급 안내 | F4: 조회 결과 안내 | G4: N | H4: 회원 | I4: 발급유형판단 | J4: 추가 발급 대상 여부를 처리계 조회하여 고객앞 안내 | L4: 추가 필요
A5: 준비사항 | B5: 0004 | C5: Y | D5: N | E5: 준비사항 | F5: 단순안내 | G5: N | H5: N | I5: - | J5: 단순안내
A6: 제출서류 | B6: 0005 | C6: Y | D6: N | E6: 제출서류 | F6: 단순안내 | G6: N | H6: N | I6: - | J6: 단순안내
A7: 서류자동제출서비스 | B7: 0006 | D7: N | E7: 서류자동제출서비스 | F7: 외부 조회 | G7: N | H7: N | I7: - | J7: - 외부 서비스 Kodata를 이용하여 고객이 해당 사이트가 제공하는 제출 서류 대행 관련 WEb 서비스를 신청하고 복귀한다. [* 해당 서비스는 고객의 사업자등록증, 법인 전체 등기확인서를 고객을 대행하여 당사 서버로 제출해주는 서비스이며배치 작업으로 당사 제공- 실시간 아님]
A8: 유의사항 | B8: 0007 | C8: Y | D8: N | E8: 유의사항 | F8: 단순안내 | G8: N | H8: N | I8: - | J8: 단순안내
A9: 법인 공동인증서(기업용)이용안내 | B9: 0008 | C9: Y | D9: N | E9: 법인 공동인증서(기업용)이용안내 | F9: 거래분개 | G9: 공용/개별 선택 | H9: N | I9: - | J9: 공용/개별카드의 분개가 발생한다.
A10: 신용카드 상품 약관동의 | B10: 0009 | C10: Y | D10: N | E10: 신용카드 상품 약관동의 | F10: 고객동의 | G10: 동의여부 | H10: N | I10: - | J10: 상품/회원 약관 필수 동의 ㅇ 동의 없이는 다음단계 진행 불가 ㅇ 여기에 '소기업' 등 공공 마이데이터 동의 정보 반드시 추가 공공 마데 정보는 해당 고객 당사 회원 탈회시까지 유효
A11: 신청인정보 | B11: 0010 | C11: Y | D11: N | E11: 신청인정보 | F11: 정보입력 | G11: 대표자 여부 신청인 성명 주민번호 휴대폰 번호 | H11: 회원 | I11: 회원원자에서 대표자 정보 ㅇ 신청인 성명 ㅇ 주민등록번호 ㅇ 휴대폰 번호 SET 없는 경우 고객이 입력 | J11: 0
A12: 신청자 신용정보 조회 이용 동의(대표자 /대리인) 신설필요 | B12: 0011 | C12: Y | D12: N | E12: 신청자 신용정보 조회 이용 동의(대표자 /대리인) 신설필요 | F12: 고객동의 | G12: 동의여부 | H12: N | J12: 신용정보조회 필수 동의 ㅇ 동의없이 다음 단계 진행 불가 ㅇ 대리인 /대표자 공용
A13: 신청인 본인인증 | B13: 0012 | C13: Y | D13: N | E13: 신청인 본인인증 | F13: 고객인증 | G13: ㅇ 인증방법에 따라 1.카드번호 2.휴대폰 번호 3.인증서 정보 를 고객이 선택하여 입력 | H13: 고객 | I13: ㅇ 본인인증 거래수행 | J13: 신청인(대표자 or 대리인) 본인인증 이며 인증방법은 3가지 이다 ㅇ 이 거래 시점에서 CDD 대상 여부를 '고객IT"로 전문 조회한다. ㅇ 거래 결과 여부에 따라 CDD 등록 조건부 검증 을 실행한다
A14: 신청인 CDD 조건부 검증(신설필요) | B14: 0013 | C14: Y | D14: N | E14: 신청인 CDD 조건부 검증(신설필요) | F14: 정보입력 | G14: 고객식별 Key 주민번호 기준 ㅇ 신청인 성명 ㅇ 신청인 영문명 ㅇ 신청인 자택주수 ㅇ 신청인 신분증 정보 ㅇ 신청인 직업 ㅇ 신청인 직업 구분 상세 ㅇ 거래목적 ㅇ 거래자금 원천 | H14: 고객 | I14: ㅇ 고객 확인 의무 대상 판단 | J14: 고객 원장 정보가 있는 경우 조회 하여 출력 한다 ㅇ 모든 항목이 필수값이며 Null로 진행이 불가하다. ㅇ 미입력 시 > ㅇㅇㅇ 값을 선택해 주세요로 에러 처리
A15: 대표자 정보 | B15: 0014 | C15: Y | D15: N | E15: 대표자 정보 | F15: 정보입력 | G15: ㅇ 대표자 성명 ㅇ 대표자 영문성명 | H15: 회원 | I15: ㅇ 회원원장에서 대표자 정보 있는 경우 회우언원장 정보 사용 ㅇ 없느 경우 고객 입력 | J15: 고객 원장 정보가 있는 경우 조회 하여 출력 한다 ㅇ 모든 항목이 필수값이며 Null로 진행이 불가하다. ㅇ 미입력 시 > ㅇㅇㅇ 값을 선택해 주세요로 에러 처리
A16: 사업자 정보 | B16: 0015 | C16: Y | D16: N | E16: 사업자 정보 | F16: 정보입력 | G16: ㅇ 사업자번호 ㅇ 업체명 ㅇ 업체 영문명 ㅇ 전화번호 ㅇ 주소 ㅇ 설립일 | H16: 회원 | I16: ㅇ 회원원장에서 대표자 정보 있는 경우 회우언원장 정보 사용 ㅇ 없느 경우 고객 입력 | J16: ㅇ 사업자 번호는 전세션에서 고객이 입력한 값을 가지고 온다
A17: 법인 정보 | B17: 0016 | C17: Y | D17: N | E17: 법인 정보 | F17: 정보입력 | G17: ㅇ 법인등록번호 ㅇ 법인명 ㅇ 전화번호 ㅇ 주소 | H17: 고객 | I17: ㅇ 고객 원장에서 법인등록번호 법인명 전화번호 주소 조회 ㅇ 없는 경우 고객 입력 | J17: 고객 원장 정보가 있는 경우 아래 값은 조회 하여 출력 한다 ㅇ 법인등록번호 ㅇ 법인명 ㅇ 모든 항목이 필수값이며 Null로 진행이 불가하다. ㅇ 미입력 시 > ㅇㅇㅇ 값을 선택해 주세요로 에러 처리
A18: EDD정보 | B18: 0017 | C18: Y | D18: N | E18: EDD정보 | F18: 정보입력 | G18: 사업자번호가 구분 Key ㅇ 거래 목적 ㅇ 거래자금의 원천 | H18: N | I18: - | J18: ㅇ 고객이 항목을 선택한다. 텍스트 입력이 아닌 선택형 메뉴 노출이다
A19: 필수확인사항 | B19: 0018 | C19: Y | D19: N | E19: 필수확인사항 | F19: 정보입력 | G19: ㅇ 별도 유효성 체크 로직 | H19: N | I19: - | J19: ㅇ 기존 가능 결제일 선택 범위 확인 필요 > 플랫폼 개발부 기존 요건 확인 ㅇ 별도 유효성 체크로직 플랫폼 개발부 확인 요
A20: 이용한도 | B20: 0019 | C20: Y | D20: N | E20: 이용한도 | F20: 정보입력 | G20: ㅇ 이용한도 | H20: N | I20: - | J20: ㅇ 이용한도는 10만원 단위로 입력한다
A21: 명세서 받으실 곳 | B21: 0020 | C21: Y | D21: N | E21: 명세서 받으실 곳 | F21: 정보입력 | G21: ㅇ 이메일, app, 우편중 선택 ㅇ 수령 방법이 이메일인 경우 또는 경우 이메일이 필수 ㅇ 특정 상품코드인 경우 이메일이 필수다 | H21: N | I21: - | J21: ㅇ 명세서 받으실 곳 선택
A22: 카드선택 | B22: 0021 | C22: Y | D22: N | E22: 카드선택 | F22: 정보입력 | G22: ㅇ 브랜드 선택 : 3중 택일 | H22: N | J22: 국내 전용 카드 선택 시 ㅇ 해외원화결제 차당 서비스 disable
A23: 결제일 | B23: 0022 | C23: Y | D23: N | E23: 결제일 | F23: 정보조회 | G23: ㅇ "필수확인사항" 에서 가져옴 ㅇ disable. | H23: 회원 | I23: ㅇ 회원 원장에서 기존 정보 조회 ㅇ 고객이 바꿀 수 있음 | J23: ㅇ 기존 가능 결제일 선택 범위 확인 필요 > 플랫폼 개발 부 요건 확인 ㅇ 고객이 변경 가능
A24: 결제계좌 | B24: 0023 | C24: Y | D24: N | E24: 결제계좌 | F24: 정보입력 | G24: ㅇ 결제계좌 | H24: 회원 | I24: ㅇ 계좌 유효성 및 본인 계좌 체크 | J24: ㅇ 회원 전문으로 결제 계좌 유효성 체크 필요
A25: 신청매수 | B25: 0024 | C25: Y | D25: N | E25: 신청매수 | F25: 정보입력 | G25: ㅇ 공용카드 신청매수 ㅇ 개별카드는 신청매수 항목없음 | H25: N | I25: - | J25: ㅇ 신청매수를 입력 받음 , 최대 매수 기존과 동일
A26: 발급 확인 및 약관수령 | B26: 0025 | C26: Y | D26: N | E26: 발급 확인 및 약관수령 | F26: 정보입력 | G26: ㅇ 약관 수령 방법 선택 ㅇ 이메일 선택시 이메일 필수 | H26: N | I26: - | J26: ㅇ 고객으로부터 이메일 문자 , 우편 중 세가지 방법 중 하나로 약관 수령 방법을 운영 한다 . ㅇ 우편은 가급적 노출시키지 않는다.
A27: 카드수령지 | B27: 0026 | C27: Y | D27: N | E27: 카드수령지 | F27: 정보입력 | G27: ㅇ 카드 수령지 ㅇ 수령동의 ㅇ 수령인 정보는 ㅇ 휴대폰 | H27: N | J27: 카드 수령지를 ㅇ 사업장 ㅇ 제3청구지 중 선택한다 수령인 정보, 휴대폰 정보는 전세션에서 가져와서 Disable한다
A28: 추천인 | B28: 0027 | C28: Y | D28: N | E28: 추천인 | F28: 정보입력 | G28: ㅇ 권유자 유형코드 입력 | H28: 공통 | I28: ㅇ 공통 조회에서 직원 정보 조회 를 조회한다. | J28: ㅇ 직원 정보 조회시 카드 은행을 구분하여 제공한다 . ㅇ 은행 선택시 K로 시작하지 않는 코드 해당 직원 정보만 display ㅇ 카드 선택시 K로 시작하는 코드 해당 직원정보만 display
A29: 공동인증서 인증 | B29: 0028 | C29: Y | D29: N | E29: 공동인증서 인증 | F29: 고객인증 | G29: ㅇ인증서 | H29: N | I29: - | J29: ㅇ 공인인증
A30: 카드정보(확인용) | B30: 0029 | C30: Y | D30: N | E30: 카드정보(확인용) | F30: 정보조회 | G30: N | H30: N | I30: - | J30: ㅇ 이전 세션 결과
A31: 사업자정보(확인용) | B31: 0030 | C31: Y | D31: N | E31: 사업자정보(확인용) | F31: 정보조회 | G31: N | H31: N | I31: - | J31: ㅇ 이전 세션 결과
A32: 대표자정보(확인용) | B32: 0031 | C32: Y | D32: N | E32: 대표자정보(확인용) | F32: 정보조회 | G32: N | H32: N | I32: - | J32: ㅇ 이전 세션 결과
A33: 법인인증 | B33: 0032 | C33: Y | D33: N | E33: 법인인증 | F33: 고객인증 | G33: ㅇ 대표자의 휴대폰 본인 인증 또는 법인인감즈명서 파일 업로드 | H33: N | I33: - | J33: ㅇ 대표자의 휴대폰 본인 인증 또는 법인인감증명서 파일 업로드 중 한가지의 형태로 인증한다
A34: 추가서류제출 | B34: 0033 | C34: Y | D34: N | E34: 추가서류제출 | F34: 정보입력 | G34: ㅇ 사업자등록증 ㅇ 법인등기부 ㅇ 주주명부 및 정관 ㅇ 신청인 신분증 은 필수 상기 위외 항목은 ㅇ 선택으로 제공받는다. ㅇ 업로드 파일 형식은 PDF , 그림(jpg, png,tff 등을 허용한다) ㅇ 수정하기를 허용하고 > 수정하기 버튼을 누르면 "명세서 받으실 곳(ID:0020)"으로 간다 | H34: N | J34: ㅇ 필수 항목은 반드시 받아야 다음으로 넘어간다
A35: 신청완료 | B35: 0034 | C35: Y | D35: N | E35: 신청완료 | F35: 정보조회 | G35: N | H35: N | I35: - | J35: ㅇ 단순 정보성 조회
A36: 개별 카드 회원 동의서 작성안내 | B36: 0035 | C36: Y | D36: N | E36: 개별 카드 회원 동의서 작성안내 | F36: 고객동의 | G36: N | H36: N | I36: - | J36: ㅇ 확인해습니다항목에 고객 확인 필요
A37: 개별카드 사용자 개인명의계좌 등록- 개별 | B37: 0036 | C37: Y | D37: N | E37: 개별카드 사용자 개인명의계좌 등록- 개별 | F37: 고객동의 | G37: ㅇ 개별신청 고객의 경우 해당 고객의 결제 계좌를 등록 필요 ㅇ 해당 고객이 개인명의 계좌 등록안내에 동의한 경우 실시간으로 LMS 발송 함 ㅇ LMS 발송을 통한 "결제 계좌 등록 프로세스 "가 별도 있으나 작동 점검 필요 | H37: 회원 | I37: ㅇ 개별카드의 개인 명의 계좌 등롟 ㅣ 본인 계좌여부 체크 필요 | J37: ㅇ 고객의 선택에 따라 등록 또는 비등록으로 고객선택 ㅇ 고객이 등록으로 선택하는 경우 "개별카드 사용자의 개인 명의 계좌로 등록되므로 이에대한 검증 프로세스가 있는지 " 플랫폼 서비스에 QA 필요
A38: 개별카드 발급 대상 고객 정보- 개별 | B38: 0037 | C38: Y | D38: N | E38: 개별카드 발급 대상 고객 정보- 개별 | F38: 정보입력 | G38: ㅇ 개별카드 대상자의 정보 입력 - 성명 - 주민번호 - 휴대폰번호 ㅇ 필수동의서 작성 요청 하기 LMS 발송 기능 필요 | H38: 회원 | I38: - | J38: 정보 모든 항목이 필수값이며 Null로 진행이 불가하다.입력 미입력 시 > ㅇㅇ정보 값을 선택해 주세요로 에러 처리
A39: 개별카드 동의 조회(조회하기)- 개별 | B39: 0038 | C39: Y | D39: N | E39: 개별카드 동의 조회(조회하기)- 개별 | F39: 정보입력 | G39: N | H39: 심사 | I39: - | J39: ㅇ 고객이 새로 고침을 눌렀을때 동의서 작성 여부 값 체크 ㅇ 동의서 작성 시 "동의서 작성 재요청하기" 버튼을 > "카드신청하기" 버튼으로 변경함 ㅇ "카드신청하기 " 버튼 클릭시 카드 신청 프로세스 재개함
A40: 개인신용정보 동의서 - 개별 | B40: 0039 | C40: Y | D40: N | E40: 개인신용정보 동의서 - 개별 | F40: 정보입력 | G40: ㅇ 버튼클릭 | H40: 회원 ㅇ 동의 정보를 플랫폼 내부에 저장하는지 , 처리계 거래를 호출하는 지 플랫폼 개발부에 확인 필요 | I40: ㅇ 본인인증 거래수행 | J40: ㅇ 본인인증 선택시 "신청인 본인인증" (ID:0012)절차 진행
...

Sheet 주요 개발 체크 리스트
A1: 순번 | B1: 구분 | C1: 조치 결과 / 대응방안
A2: 1 | B2: ㅇ 고객이 중간에서 나가 더라라도 직전까지의 단계에서 다시 시작할 수 있다.
A3: 2 | B3: ㅇ 세션 관리를 통해 다른 고객의 정보가 중간에 연결되지 않도록 정합성을 유지한다
A4: 3 | B4: ㅇ 모든 정보는 이전 세션에서 있는 정보는 이전세션에서 가져오고 회원원장 또는 고객 원장을 가져오고 없는 값만 고객에게 받는다 ㅇ 즉 고객이 입력하는 정보는 최도화한다
A5: 4 | B5: ㅇ 모든 정보는 고객이 수정가능하도록 하는 것을 원칙으로 한다. 다만 아래의 경우에는 Disable 상태로 진행한다 1. 이전 세션에서 확정된 정보 2. 원장의 참조용 안내 정보로만 보여주는 경우 3. 고객 수정시는 포멧이나 범위 같은 유효성 규칙을 검증 규칙을 넣도록 한다.
A6: 5 | B6: ㅇ 고객정보 입력시는 포멧 레이아웃에 맞추어 항목별 유휴성 검증 규칙을 둔다 ex) 영문명: 영문자만 , 전화번호: 숫자만, 지역번호 검증, 0505 070허용 등등
A7: 6 | B7: ㅇ 모든 처리계(고객 ,회원) 업데이트를 위한 전문 거래시는 전문 처리 결과를 남겨넣고 전문거래 실패 시는 더 이상 진행하지 않는다 >검증 없이 통과해서 처리계로 쓰레기 정보가 들어오는 경우 진상형 민원으로 이어질 가능성이 높다
A8: 7 | B8: ㅇ 고객 인입시 카드 발급 제한 사항을 우선 검증한다 ㅇ 발급 제한 여부 사유 존재 기 접수 거절 > 대면 안내 , 콜센터 안내 ㅇ 개인 정보 처리 정지 > 고객앞 처리 정지 해제 후 신청 안내 ㅇ 최근 1개월 이내 동일 사유 2회이상 반송시 접수 거절 > 콜센터 안내 > 고객이 많은 단계를 진행하고 나서 거절될 수록 개민원으로 발전한다. > 어차피 거절할 거면 사전에 거절하는게 맞다
A9: 8 | B9: CDD/EDD 대상 개인 고객의 경우 1. 프로세스 CDD/EDD를 등록완료 or 2. CDD/EDD 등록 불가 응답이 오는 경우 사유를 안내하고 대면 접수로 안내함다.
A10: 9 | B10: ㅇ 서비스 목록 ID의 기능 요소는 특별한 사유가 없는한 표준화하거나 통합하여 공통 사용하는 것을 원칙으로 한다 예시) 기존 : 대리인/ 대표자 신죵정보 동의 프로세스 분리 변경: 개리인/대표자 신용정보 동의 프로세스를 한 개의 서비스로 통합
A11: 10 | B11: ㅇ 이름이 동일해 보이는 서비스 ID인 경우라도 실제로 다른 경우가 존재할 수 있다는점 유의한다 . 예) 기본정보 - 업체명, 영문명, 전화번호, 주소 기본정보 2 - 업체명과, 영문명만 있음 ㅇ 동항목 분석결과 두개를 통합해서 이득이 있다고 판단되는 경우 통합가능 통합시에는 항목이 많은 쪽으로 통합 원칙 > 기존에 유사한 항목들이 다르게 분리된 이유는 해당 항목들이 공통 기능 요소가 아닌 개별 시나리오의 개별 항목으로 설계자가 모두 달랐기 때문에 다른 형식을 가짐
A12: 11 | B12: ㅇ 체크는 신용카드 방법론에서 아래 두가지가 제거됨 - 필수 확인사항 - 이용한도
A13: 12 | B13: ㅇ 서비스 목록의 기능 요소를 정의 할때 아래와 같은 요소들 의정의가 필요 - 회원/고객 거래를 타는지 안타는지 탄다면 어떤거래를 타는지 - 기능 요소의 역할: 동의인지, 정보조회인지, 정보입력인지. 기능 단위 역할 타입 구분 필요 ㅇ 해당 기능 요소에 어떤 정보들이 들어가 있는지 와 원천 구분 필요 - 고객아 입력하는 것인지, 이전세션에서 물고온것인지, 회원 원장에서 조회한 값인지
... A15: 14 | B15: ㅇ 추천인 또는 권유자 코드를 보여줄때는 은행 카드를 분리해서 보여주도록 함. 1)안 두개의 창으로 출력 2안)은행우선 정렬 카드 나중 정렬 3) 선택때부터 은행 카드르 선택하고 즉 인덱스위한 db범위를 축소하고 그다음에 이름 조회하도록 계층화 조회

Sheet 서비스 목록 ID 점검
A1: 화면기능목록 | B1: 기능록록 ID | C1: 법인사업자 | D1: 개인사업자 | E1: 화면기능목록 | F1: Action | G1: 입력값 형태 | H1: 처리계 조회 | I1: 목적 | J1: 기능 내용
A2: 사업자번호입력 | B2: 0001 | C2: Y | D2: 0 | E2: 사업자번호입력 | F2: 정보입력 | G2: 사업자번호 | H2: 회원 | I2: 신규/추가 발급 대상 여부를 처리계 조회
A3: 신규 대상 통합 발급 안내 | B3: 0002 | C3: Y | D3: 0 | E3: 신규 대상 통합 발급 안내 | F3: 조회 결과 안내 | G3: N | H3: 회원 | I3: 신규 발급 대상 여부를 처리계 조회하여 고객앞 안내
A4: 추가 대상 통합 발급 안내 | B4: 0003 | C4: Y | D4: 0 | E4: 추가 대상 통합 발급 안내 | F4: 조회 결과 안내 | G4: N | H4: 회원 | I4: 추가 발급 대상 여부를 처리계 조회하여 고객앞 안내
A5: 준비사항 | B5: 0004 | C5: Y | D5: 0 | E5: 준비사항 | F5: 단순안내 | G5: N | H5: N | I5: 단순안내
A6: 제출서류 | B6: 0005 | C6: Y | D6: 0 | E6: 제출서류 | F6: 단순안내 | G6: N | H6: N | I6: 단순안내
A7: 서류자동제출서비스 | B7: 0006 | C7: Y | D7: 0 | E7: 서류자동제출서비스 | F7: 외부 조회 | G7: N | H7: N | I7: - 외부 서비스 Kodata를 이용하여 고객이 해당 사이트가 제공하는 제출 서류 대행 관련 WEb 서비스를 신청하고 복귀한다. [* 해당 서비스는 고객의 사업자등록증, 법인 전체 등기확인서를 고객을 대행하여 당사 서버로 제출해주는 서비스이며배치 작업으로 당사 제공- 실시간 아님]
A8: 유의사항 | B8: 0007 | C8: Y | D8: 0 | E8: 유의사항 | F8: 단순안내 | G8: N | H8: N | I8: 단순안내
A9: 법인 공동인증서(기업용)이용안내 | B9: 0008 | C9: Y | D9: 0 | E9: 법인 공동인증서(기업용)이용안내 | F9: 거래분개 | G9: 공용/개별 선택 | H9: N | I9: 공용/개별카드의 분개가 발생한다.
A10: 신용카드 상품 약관동의 | B10: 0009 | C10: Y | D10: 0 | E10: 신용카드 상품 약관동의 | F10: 고객동의 | G10: 동의여부 | H10: N | I10: 상품/회원 약관 필수 동의 ㅇ 동의 없이는 다음단계 진행 불가 ㅇ 여기에 '소기업' 등 공공 마이데이터 동의 정보 반드시 추가 공공 마데 정보는 해당 고객 당사 회원 탈회시까지 유효
A11: 신청인정보 | B11: 0010 | C11: Y | D11: 0 | E11: 신청인정보 | F11: 정보입력 | G11: 대표자 여부 신청인 성명 주민번호 휴대폰 번호 | H11: N | I11: 0
A12: 신청자 신용정보 조회 이용 동의(대표자 /대리인) 신설필요 | B12: 0011 | C12: Y | D12: 0 | E12: 신청자 신용정보 조회 이용 동의(대표자 /대리인) 신설필요 | F12: 고객동의 | G12: 동의여부 | H12: N | I12: 신용정보조회 필수 동의 ㅇ 동의없이 다음 단계 진행 불가 ㅇ 대리인 /대표자 공용
A13: 신청인 본인인증 | B13: 0012 | C13: Y | D13: 0 | E13: 신청인 본인인증 | F13: 고객인증 | G13: ㅇ 인증방법에 따라 1.카드번호 2.휴대폰 번호 3.인증서 정보 를 고객이 선택하여 입력 | H13: 고객 | I13: 신청인(대표자 or 대리인) 본인인증 이며 인증방법은 3가지 이다 ㅇ 이 거래 시점에서 CDD 대상 여부를 '고객IT"로 전문 조회한다. ㅇ 거래 결과 여부에 따라 CDD 등록 조건부 검증 을 실행한다
A14: 신청인 CDD 조건부 검증(신설필요) | B14: 0013 | C14: Y | D14: 0 | E14: 신청인 CDD 조건부 검증(신설필요) | F14: 정보입력 | G14: 고객식별 Key 주민번호 기준 ㅇ 신청인 성명 ㅇ 신청인 영문명 ㅇ 신청인 자택주수 ㅇ 신청인 신분증 정보 ㅇ 신청인 직업 ㅇ 신청인 직업 구분 상세 ㅇ 거래목적 ㅇ 거래자금 원천 | H14: 고객 | I14: 고객 원장 정보가 있는 경우 조회 하여 출력 한다 ㅇ 모든 항목이 필수값이며 Null로 진행이 불가하다. ㅇ 미입력 시 > ㅇㅇㅇ 값을 선택해 주세요로 에러 처리
A15: 대표자 정보 | B15: 0014 | C15: Y | D15: 0 | E15: 대표자 정보 | F15: 정보입력 | G15: ㅇ 대표자 성명 ㅇ 대표자 영문성명 | H15: N | I15: 고객 원장 정보가 있는 경우 조회 하여 출력 한다 ㅇ 모든 항목이 필수값이며 Null로 진행이 불가하다. ㅇ 미입력 시 > ㅇㅇㅇ 값을 선택해 주세요로 에러 처리
A16: 사업자 정보 | B16: 0015 | C16: Y | D16: 0 | E16: 사업자 정보 | F16: 정보입력 | G16: ㅇ 사업자번호 ㅇ 업체명 ㅇ 업체 영문명 ㅇ 전화번호 ㅇ 주소 ㅇ 설립일 | H16: N | I16: ㅇ 사업자 번호는 전세션에서 고객이 입력한 값을 가지고 온다
A17: 법인 정보 | B17: 0016 | C17: Y | D17: 0 | E17: 법인 정보 | F17: 정보입력 | G17: ㅇ 법인등록번호 ㅇ 법인명 ㅇ 전화번호 ㅇ 주소 | H17: N | I17: 고객 원장 정보가 있는 경우 아래 값은 조회 하여 출력 한다 ㅇ 법인등록번호 ㅇ 법인명 ㅇ 모든 항목이 필수값이며 Null로 진행이 불가하다. ㅇ 미입력 시 > ㅇㅇㅇ 값을 선택해 주세요로 에러 처리
A18: EDD정보 | B18: 0017 | C18: Y | D18: 0 | E18: EDD정보 | F18: 정보입력 | G18: 사업자번호가 구분 Key ㅇ 거래 목적 ㅇ 거래자금의 원천 | H18: N | I18: ㅇ 고객이 항목을 선택한다. 텍스트 입력이 아닌 선택형 메뉴 노출이다
A19: 필수확인사항 | B19: 0018 | C19: Y | D19: 0 | E19: 필수확인사항 | F19: 정보입력 | G19: ㅇ 별도 유효성 체크 로직 | H19: N | I19: ㅇ 기존 가능 결제일 선택 범위 확인 필요 > 플랫폼 개발부 기존 요건 확인 ㅇ 별도 유효성 체크로직 플랫폼 개발부 확인 요
A20: 이용한도 | B20: 0019 | C20: Y | D20: 0 | E20: 이용한도 | F20: 정보입력 | G20: ㅇ 이용한도 | H20: N | I20: ㅇ 이용한도는 10만원 단위로 입력한다
A21: 명세서 받으실 곳 | B21: 0020 | C21: Y | D21: 0 | E21: 명세서 받으실 곳 | F21: 정보입력 | G21: ㅇ 이메일, app, 우편중 선택 ㅇ 수령 방법이 이메일인 경우 또는 경우 이메일이 필수 ㅇ 특정 상품코드인 경우 이메일이 필수다 | H21: N | I21: ㅇ 명세서 받으실 곳 선택
A22: 카드선택 | B22: 0021 | C22: Y | D22: 0 | E22: 카드선택 | F22: 정보입력 | G22: ㅇ 브랜드 선택 : 3중 택일 | H22: N | I22: 국내 전용 카드 선택 시 ㅇ 해외원화결제 차당 서비스 disable
A23: 결제일 | B23: 0022 | C23: Y | D23: 0 | E23: 결제일 | F23: 정보조회 | G23: ㅇ "필수확인사항" 에서 가져옴 ㅇ disable. | H23: N | I23: ㅇ 기존 가능 결제일 선택 범위 확인 필요 > 플랫폼 개발 부 요건 확인
... A53: 신청완료- 카드신청정보(확인용) | B53: 0052 | C53: Y | D53: 0 | E53: 신청완료- 카드신청정보(확인용) | F53: 정보조회 | G53: N | H53: 회원 | I53: ㅇ 회원 정보를 읽는 건지 플랫폼자체 db를 읽는건지 확인 필요
A54: 0 | B54: 0053 | C54: Y | D54: 0 | E54: 0 | G54: 0 | H54: 0 | I54: 0
A55: 0 | B55: 0054 | C55: Y | D55: 0 | E55: 0 | G55: 0 | H55: 0 | I55: 0
A56: 0 | B56: 0055 | C56: Y | D56: 0 | E56: 0 | G56: 0 | H56: 0 | I56: 0
A57: 0 | B57: 0056 | C57: Y | D57: 0 | E57: 0 | G57: 0 | H57: 0 | I57: 0
A58: 0 | B58: 0057 | C58: Y | D58: 0 | E58: 0 | G58: 0 | H58: 0 | I58: 0
A59: 0 | B59: 0058 | C59: Y | D59: 0 | E59: 0 | G59: 0 | H59: 0 | I59: 0
A60: 0 | B60: 0059 | C60: 0 | D60: 0 | E60: 0 | G60: 0 | H60: 0 | I60: 0
A61: 0 | B61: 0060 | C61: 0 | D61: 0 | E61: 0 | G61: 0 | H61: 0 | I61: 0
A62: 0 | B62: 0061 | C62: 0 | D62: 0 | E62: 0 | G62: 0 | H62: 0 | I62: 0
A63: 0 | B63: 0062 | C63: 0 | D63: 0 | E63: 0 | G63: 0 | H63: 0 | I63: 0
A64: 0 | B64: 0 | C64: 0 | D64: 0 | E64: 0 | G64: 0 | H64: 0 | I64: 0
A65: 0 | B65: 0 | C65: 0 | D65: 0 | E65: 0 | G65: 0 | H65: 0 | I65: 0
A66: 0 | B66: 0 | C66: 0 | D66: 0 | E66: 0 | G66: 0 | H66: 0 | I66: 0
A67: 0 | B67: 0 | C67: 0 | D67: 0 | E67: 0 | G67: 0 | H67: 0 | I67: 0
A68: 0 | B68: 0 | C68: 0 | D68: 0 | E68: 0 | G68: 0 | H68: 0 | I68: 0
A69: 0 | B69: 0 | C69: 0 | D69: 0 | E69: 0 | G69: 0 | H69: 0 | I69: 0
...
